2021-06-16 16:20:07,582:WARNING: Setting up a new session...
Traceback (most recent call last):
  File "/opt/conda/lib/python3.7/site-packages/urllib3/connection.py", line 160, in _new_conn
    (self._dns_host, self.port), self.timeout, **extra_kw
  File "/opt/conda/lib/python3.7/site-packages/urllib3/util/connection.py", line 84, in create_connection
    raise err
  File "/opt/conda/lib/python3.7/site-packages/urllib3/util/connection.py", line 74, in create_connection
    sock.connect(sa)
ConnectionRefusedError: [Errno 111] Connection refused

During handling of the above exception, another exception occurred:

Traceback (most recent call last):
  File "/opt/conda/lib/python3.7/site-packages/urllib3/connectionpool.py", line 677, in urlopen
    chunked=chunked,
  File "/opt/conda/lib/python3.7/site-packages/urllib3/connectionpool.py", line 392, in _make_request
    conn.request(method, url, **httplib_request_kw)
  File "/opt/conda/lib/python3.7/http/client.py", line 1262, in request
    self._send_request(method, url, body, headers, encode_chunked)
  File "/opt/conda/lib/python3.7/http/client.py", line 1308, in _send_request
    self.endheaders(body, encode_chunked=encode_chunked)
  File "/opt/conda/lib/python3.7/http/client.py", line 1257, in endheaders
    self._send_output(message_body, encode_chunked=encode_chunked)
  File "/opt/conda/lib/python3.7/http/client.py", line 1028, in _send_output
    self.send(msg)
  File "/opt/conda/lib/python3.7/http/client.py", line 968, in send
    self.connect()
  File "/opt/conda/lib/python3.7/site-packages/urllib3/connection.py", line 187, in connect
    conn = self._new_conn()
  File "/opt/conda/lib/python3.7/site-packages/urllib3/connection.py", line 172, in _new_conn
    self, "Failed to establish a new connection: %s" % e
urllib3.exceptions.NewConnectionError: <urllib3.connection.HTTPConnection object at 0x7f423ecf0190>: Failed to establish a new connection: [Errno 111] Connection refused

During handling of the above exception, another exception occurred:

Traceback (most recent call last):
  File "/opt/conda/lib/python3.7/site-packages/requests/adapters.py", line 449, in send
    timeout=timeout
  File "/opt/conda/lib/python3.7/site-packages/urllib3/connectionpool.py", line 727, in urlopen
    method, url, error=e, _pool=self, _stacktrace=sys.exc_info()[2]
  File "/opt/conda/lib/python3.7/site-packages/urllib3/util/retry.py", line 439, in increment
    raise MaxRetryError(_pool, url, error or ResponseError(cause))
urllib3.exceptions.MaxRetryError: HTTPConnectionPool(host='localhost', port=8097): Max retries exceeded with url: /env/main (Caused by NewConnectionError('<urllib3.connection.HTTPConnection object at 0x7f423ecf0190>: Failed to establish a new connection: [Errno 111] Connection refused'))

During handling of the above exception, another exception occurred:

Traceback (most recent call last):
  File "/home/hpc-0235/.local/lib/python3.7/site-packages/visdom/__init__.py", line 711, in _send
    data=json.dumps(msg),
  File "/home/hpc-0235/.local/lib/python3.7/site-packages/visdom/__init__.py", line 677, in _handle_post
    r = self.session.post(url, data=data)
  File "/opt/conda/lib/python3.7/site-packages/requests/sessions.py", line 578, in post
    return self.request('POST', url, data=data, json=json, **kwargs)
  File "/opt/conda/lib/python3.7/site-packages/requests/sessions.py", line 530, in request
    resp = self.send(prep, **send_kwargs)
  File "/opt/conda/lib/python3.7/site-packages/requests/sessions.py", line 643, in send
    r = adapter.send(request, **kwargs)
  File "/opt/conda/lib/python3.7/site-packages/requests/adapters.py", line 516, in send
    raise ConnectionError(e, request=request)
requests.exceptions.ConnectionError: HTTPConnectionPool(host='localhost', port=8097): Max retries exceeded with url: /env/main (Caused by NewConnectionError('<urllib3.connection.HTTPConnection object at 0x7f423ecf0190>: Failed to establish a new connection: [Errno 111] Connection refused'))
2021-06-16 16:20:07,600:INFO: Socket refused connection, running socketless
2021-06-16 16:20:07,600:ERROR: [Errno 111] Connection refused
2021-06-16 16:20:07,600:ERROR: error from callback <function Visdom.setup_socket.<locals>.on_close at 0x7f423ea7b8c0>: on_close() takes 1 positional argument but 3 were given
2021-06-16 16:20:07,700:WARNING: Setting up a new session...
Traceback (most recent call last):
  File "/opt/conda/lib/python3.7/site-packages/urllib3/connection.py", line 160, in _new_conn
    (self._dns_host, self.port), self.timeout, **extra_kw
  File "/opt/conda/lib/python3.7/site-packages/urllib3/util/connection.py", line 84, in create_connection
    raise err
  File "/opt/conda/lib/python3.7/site-packages/urllib3/util/connection.py", line 74, in create_connection
    sock.connect(sa)
ConnectionRefusedError: [Errno 111] Connection refused

During handling of the above exception, another exception occurred:

Traceback (most recent call last):
  File "/opt/conda/lib/python3.7/site-packages/urllib3/connectionpool.py", line 677, in urlopen
    chunked=chunked,
  File "/opt/conda/lib/python3.7/site-packages/urllib3/connectionpool.py", line 392, in _make_request
    conn.request(method, url, **httplib_request_kw)
  File "/opt/conda/lib/python3.7/http/client.py", line 1262, in request
    self._send_request(method, url, body, headers, encode_chunked)
  File "/opt/conda/lib/python3.7/http/client.py", line 1308, in _send_request
    self.endheaders(body, encode_chunked=encode_chunked)
  File "/opt/conda/lib/python3.7/http/client.py", line 1257, in endheaders
    self._send_output(message_body, encode_chunked=encode_chunked)
  File "/opt/conda/lib/python3.7/http/client.py", line 1028, in _send_output
    self.send(msg)
  File "/opt/conda/lib/python3.7/http/client.py", line 968, in send
    self.connect()
  File "/opt/conda/lib/python3.7/site-packages/urllib3/connection.py", line 187, in connect
    conn = self._new_conn()
  File "/opt/conda/lib/python3.7/site-packages/urllib3/connection.py", line 172, in _new_conn
    self, "Failed to establish a new connection: %s" % e
urllib3.exceptions.NewConnectionError: <urllib3.connection.HTTPConnection object at 0x7f423e20e190>: Failed to establish a new connection: [Errno 111] Connection refused

During handling of the above exception, another exception occurred:

Traceback (most recent call last):
  File "/opt/conda/lib/python3.7/site-packages/requests/adapters.py", line 449, in send
    timeout=timeout
  File "/opt/conda/lib/python3.7/site-packages/urllib3/connectionpool.py", line 727, in urlopen
    method, url, error=e, _pool=self, _stacktrace=sys.exc_info()[2]
  File "/opt/conda/lib/python3.7/site-packages/urllib3/util/retry.py", line 439, in increment
    raise MaxRetryError(_pool, url, error or ResponseError(cause))
urllib3.exceptions.MaxRetryError: HTTPConnectionPool(host='localhost', port=8097): Max retries exceeded with url: /env/main (Caused by NewConnectionError('<urllib3.connection.HTTPConnection object at 0x7f423e20e190>: Failed to establish a new connection: [Errno 111] Connection refused'))

During handling of the above exception, another exception occurred:

Traceback (most recent call last):
  File "/home/hpc-0235/.local/lib/python3.7/site-packages/visdom/__init__.py", line 711, in _send
    data=json.dumps(msg),
  File "/home/hpc-0235/.local/lib/python3.7/site-packages/visdom/__init__.py", line 677, in _handle_post
    r = self.session.post(url, data=data)
  File "/opt/conda/lib/python3.7/site-packages/requests/sessions.py", line 578, in post
    return self.request('POST', url, data=data, json=json, **kwargs)
  File "/opt/conda/lib/python3.7/site-packages/requests/sessions.py", line 530, in request
    resp = self.send(prep, **send_kwargs)
  File "/opt/conda/lib/python3.7/site-packages/requests/sessions.py", line 643, in send
    r = adapter.send(request, **kwargs)
  File "/opt/conda/lib/python3.7/site-packages/requests/adapters.py", line 516, in send
    raise ConnectionError(e, request=request)
requests.exceptions.ConnectionError: HTTPConnectionPool(host='localhost', port=8097): Max retries exceeded with url: /env/main (Caused by NewConnectionError('<urllib3.connection.HTTPConnection object at 0x7f423e20e190>: Failed to establish a new connection: [Errno 111] Connection refused'))
2021-06-16 16:20:07,706:INFO: Socket refused connection, running socketless
2021-06-16 16:20:07,706:ERROR: [Errno 111] Connection refused
2021-06-16 16:20:07,706:ERROR: error from callback <function Visdom.setup_socket.<locals>.on_close at 0x7f423e215200>: on_close() takes 1 positional argument but 3 were given
2021-06-16 16:20:07,806:WARNING: Setting up a new session...
Traceback (most recent call last):
  File "/opt/conda/lib/python3.7/site-packages/urllib3/connection.py", line 160, in _new_conn
    (self._dns_host, self.port), self.timeout, **extra_kw
  File "/opt/conda/lib/python3.7/site-packages/urllib3/util/connection.py", line 84, in create_connection
    raise err
  File "/opt/conda/lib/python3.7/site-packages/urllib3/util/connection.py", line 74, in create_connection
    sock.connect(sa)
ConnectionRefusedError: [Errno 111] Connection refused

During handling of the above exception, another exception occurred:

Traceback (most recent call last):
  File "/opt/conda/lib/python3.7/site-packages/urllib3/connectionpool.py", line 677, in urlopen
    chunked=chunked,
  File "/opt/conda/lib/python3.7/site-packages/urllib3/connectionpool.py", line 392, in _make_request
    conn.request(method, url, **httplib_request_kw)
  File "/opt/conda/lib/python3.7/http/client.py", line 1262, in request
    self._send_request(method, url, body, headers, encode_chunked)
  File "/opt/conda/lib/python3.7/http/client.py", line 1308, in _send_request
    self.endheaders(body, encode_chunked=encode_chunked)
  File "/opt/conda/lib/python3.7/http/client.py", line 1257, in endheaders
    self._send_output(message_body, encode_chunked=encode_chunked)
  File "/opt/conda/lib/python3.7/http/client.py", line 1028, in _send_output
    self.send(msg)
  File "/opt/conda/lib/python3.7/http/client.py", line 968, in send
    self.connect()
  File "/opt/conda/lib/python3.7/site-packages/urllib3/connection.py", line 187, in connect
    conn = self._new_conn()
  File "/opt/conda/lib/python3.7/site-packages/urllib3/connection.py", line 172, in _new_conn
    self, "Failed to establish a new connection: %s" % e
urllib3.exceptions.NewConnectionError: <urllib3.connection.HTTPConnection object at 0x7f423ea842d0>: Failed to establish a new connection: [Errno 111] Connection refused

During handling of the above exception, another exception occurred:

Traceback (most recent call last):
  File "/opt/conda/lib/python3.7/site-packages/requests/adapters.py", line 449, in send
    timeout=timeout
  File "/opt/conda/lib/python3.7/site-packages/urllib3/connectionpool.py", line 727, in urlopen
    method, url, error=e, _pool=self, _stacktrace=sys.exc_info()[2]
  File "/opt/conda/lib/python3.7/site-packages/urllib3/util/retry.py", line 439, in increment
    raise MaxRetryError(_pool, url, error or ResponseError(cause))
urllib3.exceptions.MaxRetryError: HTTPConnectionPool(host='localhost', port=8097): Max retries exceeded with url: /env/main (Caused by NewConnectionError('<urllib3.connection.HTTPConnection object at 0x7f423ea842d0>: Failed to establish a new connection: [Errno 111] Connection refused'))

During handling of the above exception, another exception occurred:

Traceback (most recent call last):
  File "/home/hpc-0235/.local/lib/python3.7/site-packages/visdom/__init__.py", line 711, in _send
    data=json.dumps(msg),
  File "/home/hpc-0235/.local/lib/python3.7/site-packages/visdom/__init__.py", line 677, in _handle_post
    r = self.session.post(url, data=data)
  File "/opt/conda/lib/python3.7/site-packages/requests/sessions.py", line 578, in post
    return self.request('POST', url, data=data, json=json, **kwargs)
  File "/opt/conda/lib/python3.7/site-packages/requests/sessions.py", line 530, in request
    resp = self.send(prep, **send_kwargs)
  File "/opt/conda/lib/python3.7/site-packages/requests/sessions.py", line 643, in send
    r = adapter.send(request, **kwargs)
  File "/opt/conda/lib/python3.7/site-packages/requests/adapters.py", line 516, in send
    raise ConnectionError(e, request=request)
requests.exceptions.ConnectionError: HTTPConnectionPool(host='localhost', port=8097): Max retries exceeded with url: /env/main (Caused by NewConnectionError('<urllib3.connection.HTTPConnection object at 0x7f423ea842d0>: Failed to establish a new connection: [Errno 111] Connection refused'))
2021-06-16 16:20:07,814:INFO: Socket refused connection, running socketless
2021-06-16 16:20:07,815:ERROR: [Errno 111] Connection refused
2021-06-16 16:20:07,815:ERROR: error from callback <function Visdom.setup_socket.<locals>.on_close at 0x7f423ecdf8c0>: on_close() takes 1 positional argument but 3 were given
2021-06-16 16:20:07,914:WARNING: Setting up a new session...
Traceback (most recent call last):
  File "/opt/conda/lib/python3.7/site-packages/urllib3/connection.py", line 160, in _new_conn
    (self._dns_host, self.port), self.timeout, **extra_kw
  File "/opt/conda/lib/python3.7/site-packages/urllib3/util/connection.py", line 84, in create_connection
    raise err
  File "/opt/conda/lib/python3.7/site-packages/urllib3/util/connection.py", line 74, in create_connection
    sock.connect(sa)
ConnectionRefusedError: [Errno 111] Connection refused

During handling of the above exception, another exception occurred:

Traceback (most recent call last):
  File "/opt/conda/lib/python3.7/site-packages/urllib3/connectionpool.py", line 677, in urlopen
    chunked=chunked,
  File "/opt/conda/lib/python3.7/site-packages/urllib3/connectionpool.py", line 392, in _make_request
    conn.request(method, url, **httplib_request_kw)
  File "/opt/conda/lib/python3.7/http/client.py", line 1262, in request
    self._send_request(method, url, body, headers, encode_chunked)
  File "/opt/conda/lib/python3.7/http/client.py", line 1308, in _send_request
    self.endheaders(body, encode_chunked=encode_chunked)
  File "/opt/conda/lib/python3.7/http/client.py", line 1257, in endheaders
    self._send_output(message_body, encode_chunked=encode_chunked)
  File "/opt/conda/lib/python3.7/http/client.py", line 1028, in _send_output
    self.send(msg)
  File "/opt/conda/lib/python3.7/http/client.py", line 968, in send
    self.connect()
  File "/opt/conda/lib/python3.7/site-packages/urllib3/connection.py", line 187, in connect
    conn = self._new_conn()
  File "/opt/conda/lib/python3.7/site-packages/urllib3/connection.py", line 172, in _new_conn
    self, "Failed to establish a new connection: %s" % e
urllib3.exceptions.NewConnectionError: <urllib3.connection.HTTPConnection object at 0x7f423e218710>: Failed to establish a new connection: [Errno 111] Connection refused

During handling of the above exception, another exception occurred:

Traceback (most recent call last):
  File "/opt/conda/lib/python3.7/site-packages/requests/adapters.py", line 449, in send
    timeout=timeout
  File "/opt/conda/lib/python3.7/site-packages/urllib3/connectionpool.py", line 727, in urlopen
    method, url, error=e, _pool=self, _stacktrace=sys.exc_info()[2]
  File "/opt/conda/lib/python3.7/site-packages/urllib3/util/retry.py", line 439, in increment
    raise MaxRetryError(_pool, url, error or ResponseError(cause))
urllib3.exceptions.MaxRetryError: HTTPConnectionPool(host='localhost', port=8097): Max retries exceeded with url: /env/main (Caused by NewConnectionError('<urllib3.connection.HTTPConnection object at 0x7f423e218710>: Failed to establish a new connection: [Errno 111] Connection refused'))

During handling of the above exception, another exception occurred:

Traceback (most recent call last):
  File "/home/hpc-0235/.local/lib/python3.7/site-packages/visdom/__init__.py", line 711, in _send
    data=json.dumps(msg),
  File "/home/hpc-0235/.local/lib/python3.7/site-packages/visdom/__init__.py", line 677, in _handle_post
    r = self.session.post(url, data=data)
  File "/opt/conda/lib/python3.7/site-packages/requests/sessions.py", line 578, in post
    return self.request('POST', url, data=data, json=json, **kwargs)
  File "/opt/conda/lib/python3.7/site-packages/requests/sessions.py", line 530, in request
    resp = self.send(prep, **send_kwargs)
  File "/opt/conda/lib/python3.7/site-packages/requests/sessions.py", line 643, in send
    r = adapter.send(request, **kwargs)
  File "/opt/conda/lib/python3.7/site-packages/requests/adapters.py", line 516, in send
    raise ConnectionError(e, request=request)
requests.exceptions.ConnectionError: HTTPConnectionPool(host='localhost', port=8097): Max retries exceeded with url: /env/main (Caused by NewConnectionError('<urllib3.connection.HTTPConnection object at 0x7f423e218710>: Failed to establish a new connection: [Errno 111] Connection refused'))
2021-06-16 16:20:07,923:INFO: Socket refused connection, running socketless
2021-06-16 16:20:07,923:ERROR: [Errno 111] Connection refused
2021-06-16 16:20:07,923:ERROR: error from callback <function Visdom.setup_socket.<locals>.on_close at 0x7f423e215d40>: on_close() takes 1 positional argument but 3 were given
2021-06-16 16:20:08,023:WARNING: Setting up a new session...
Traceback (most recent call last):
  File "/opt/conda/lib/python3.7/site-packages/urllib3/connection.py", line 160, in _new_conn
    (self._dns_host, self.port), self.timeout, **extra_kw
  File "/opt/conda/lib/python3.7/site-packages/urllib3/util/connection.py", line 84, in create_connection
    raise err
  File "/opt/conda/lib/python3.7/site-packages/urllib3/util/connection.py", line 74, in create_connection
    sock.connect(sa)
ConnectionRefusedError: [Errno 111] Connection refused

During handling of the above exception, another exception occurred:

Traceback (most recent call last):
  File "/opt/conda/lib/python3.7/site-packages/urllib3/connectionpool.py", line 677, in urlopen
    chunked=chunked,
  File "/opt/conda/lib/python3.7/site-packages/urllib3/connectionpool.py", line 392, in _make_request
    conn.request(method, url, **httplib_request_kw)
  File "/opt/conda/lib/python3.7/http/client.py", line 1262, in request
    self._send_request(method, url, body, headers, encode_chunked)
  File "/opt/conda/lib/python3.7/http/client.py", line 1308, in _send_request
    self.endheaders(body, encode_chunked=encode_chunked)
  File "/opt/conda/lib/python3.7/http/client.py", line 1257, in endheaders
    self._send_output(message_body, encode_chunked=encode_chunked)
  File "/opt/conda/lib/python3.7/http/client.py", line 1028, in _send_output
    self.send(msg)
  File "/opt/conda/lib/python3.7/http/client.py", line 968, in send
    self.connect()
  File "/opt/conda/lib/python3.7/site-packages/urllib3/connection.py", line 187, in connect
    conn = self._new_conn()
  File "/opt/conda/lib/python3.7/site-packages/urllib3/connection.py", line 172, in _new_conn
    self, "Failed to establish a new connection: %s" % e
urllib3.exceptions.NewConnectionError: <urllib3.connection.HTTPConnection object at 0x7f423e21be10>: Failed to establish a new connection: [Errno 111] Connection refused

During handling of the above exception, another exception occurred:

Traceback (most recent call last):
  File "/opt/conda/lib/python3.7/site-packages/requests/adapters.py", line 449, in send
    timeout=timeout
  File "/opt/conda/lib/python3.7/site-packages/urllib3/connectionpool.py", line 727, in urlopen
    method, url, error=e, _pool=self, _stacktrace=sys.exc_info()[2]
  File "/opt/conda/lib/python3.7/site-packages/urllib3/util/retry.py", line 439, in increment
    raise MaxRetryError(_pool, url, error or ResponseError(cause))
urllib3.exceptions.MaxRetryError: HTTPConnectionPool(host='localhost', port=8097): Max retries exceeded with url: /env/main (Caused by NewConnectionError('<urllib3.connection.HTTPConnection object at 0x7f423e21be10>: Failed to establish a new connection: [Errno 111] Connection refused'))

During handling of the above exception, another exception occurred:

Traceback (most recent call last):
  File "/home/hpc-0235/.local/lib/python3.7/site-packages/visdom/__init__.py", line 711, in _send
    data=json.dumps(msg),
  File "/home/hpc-0235/.local/lib/python3.7/site-packages/visdom/__init__.py", line 677, in _handle_post
    r = self.session.post(url, data=data)
  File "/opt/conda/lib/python3.7/site-packages/requests/sessions.py", line 578, in post
    return self.request('POST', url, data=data, json=json, **kwargs)
  File "/opt/conda/lib/python3.7/site-packages/requests/sessions.py", line 530, in request
    resp = self.send(prep, **send_kwargs)
  File "/opt/conda/lib/python3.7/site-packages/requests/sessions.py", line 643, in send
    r = adapter.send(request, **kwargs)
  File "/opt/conda/lib/python3.7/site-packages/requests/adapters.py", line 516, in send
    raise ConnectionError(e, request=request)
requests.exceptions.ConnectionError: HTTPConnectionPool(host='localhost', port=8097): Max retries exceeded with url: /env/main (Caused by NewConnectionError('<urllib3.connection.HTTPConnection object at 0x7f423e21be10>: Failed to establish a new connection: [Errno 111] Connection refused'))
2021-06-16 16:20:08,031:INFO: Socket refused connection, running socketless
2021-06-16 16:20:08,031:ERROR: [Errno 111] Connection refused
2021-06-16 16:20:08,031:ERROR: error from callback <function Visdom.setup_socket.<locals>.on_close at 0x7f423e21e710>: on_close() takes 1 positional argument but 3 were given
2021-06-16 16:20:08,131:INFO: dataset_dir: ./skeletons
2021-06-16 16:20:08,131:INFO: dataset_name: NTU-RGB-D-CV
2021-06-16 16:20:08,131:INFO: model_dir: ./
2021-06-16 16:20:08,131:INFO: model_name: HCN
2021-06-16 16:20:08,131:INFO: load_model: None
2021-06-16 16:20:08,131:INFO: load: False
2021-06-16 16:20:08,132:INFO: mode: train
2021-06-16 16:20:08,132:INFO: num: 01
2021-06-16 16:20:08,132:INFO: model_version: HCN
2021-06-16 16:20:08,132:INFO: experiment_path: ./experiments/NTU-RGB-D-CV/HCN01
2021-06-16 16:20:08,132:INFO: restore_file: None
2021-06-16 16:20:08,132:INFO: gpu_id: 0
2021-06-16 16:20:08,132:INFO: cuda: True
2021-06-16 16:20:08,133:INFO: data_parallel: False
2021-06-16 16:20:08,133:INFO: seed: 0
2021-06-16 16:20:08,133:INFO: lr: 0.001
2021-06-16 16:20:08,133:INFO: lr_decay_type: exp
2021-06-16 16:20:08,133:INFO: lr_step: [100, 160, 200]
2021-06-16 16:20:08,133:INFO: scheduler_gamma: 0.1
2021-06-16 16:20:08,133:INFO: scheduler_gamma2: 0.99
2021-06-16 16:20:08,133:INFO: scheduler_gamma3: 0.5
2021-06-16 16:20:08,133:INFO: patience: 20
2021-06-16 16:20:08,133:INFO: batch_size: 64
2021-06-16 16:20:08,134:INFO: num_epochs: 400
2021-06-16 16:20:08,134:INFO: start_epoch: 0
2021-06-16 16:20:08,134:INFO: save_best_ever_n_epoch: 50
2021-06-16 16:20:08,134:INFO: save_summary_steps: 1
2021-06-16 16:20:08,134:INFO: num_workers: 4
2021-06-16 16:20:08,134:INFO: optimizer: Adam
2021-06-16 16:20:08,134:INFO: weight_decay: 0.0001
2021-06-16 16:20:08,134:INFO: clip: 0.5
2021-06-16 16:20:08,134:INFO: train_feeder_args: {'data_path': None, 'label_path': None, 'random_valid_choose': False, 'random_shift': False, 'random_move': False, 'window_size': 32, 'normalization': False, 'debug': False, 'origin_transfer': 0, 'crop_resize': True, 'p_interval': [0.5, 1]}
2021-06-16 16:20:08,134:INFO: test_feeder_args: {'data_path': None, 'label_path': None, 'random_valid_choose': False, 'random_shift': False, 'random_move': False, 'window_size': 32, 'normalization': False, 'debug': False, 'origin_transfer': 0, 'crop_resize': True, 'p_interval': [0.95]}
2021-06-16 16:20:08,135:INFO: model_args: {'in_channel': 3, 'out_channel': 64, 'window_size': 32, 'num_joint': 25, 'num_person': 2, 'num_class': 60}
2021-06-16 16:20:08,135:INFO: loss_args: {'type': 'CE'}
2021-06-16 16:20:08,135:INFO: dataset_dir: ./skeletons
2021-06-16 16:20:08,135:INFO: dataset_name: NTU-RGB-D-CV
2021-06-16 16:20:08,135:INFO: mode: train
2021-06-16 16:20:20,787:INFO: HCN(
  (conv1): Sequential(
    (0): Conv2d(3, 64, kernel_size=(1, 1), stride=(1, 1))
    (1): ReLU()
  )
  (conv2): Conv2d(64, 32, kernel_size=(3, 1), stride=(1, 1), padding=(1, 0))
  (conv3): Sequential(
    (0): Conv2d(25, 32, kernel_size=(3, 3), stride=(1, 1), padding=(1, 1))
    (1): MaxPool2d(kernel_size=2, stride=2, padding=0, dilation=1, ceil_mode=False)
  )
  (conv4): Sequential(
    (0): Conv2d(32, 64, kernel_size=(3, 3), stride=(1, 1), padding=(1, 1))
    (1): Dropout2d(p=0.5, inplace=False)
    (2): MaxPool2d(kernel_size=2, stride=2, padding=0, dilation=1, ceil_mode=False)
  )
  (conv1m): Sequential(
    (0): Conv2d(3, 64, kernel_size=(1, 1), stride=(1, 1))
    (1): ReLU()
  )
  (conv2m): Conv2d(64, 32, kernel_size=(3, 1), stride=(1, 1), padding=(1, 0))
  (conv3m): Sequential(
    (0): Conv2d(25, 32, kernel_size=(3, 3), stride=(1, 1), padding=(1, 1))
    (1): MaxPool2d(kernel_size=2, stride=2, padding=0, dilation=1, ceil_mode=False)
  )
  (conv4m): Sequential(
    (0): Conv2d(32, 64, kernel_size=(3, 3), stride=(1, 1), padding=(1, 1))
    (1): Dropout2d(p=0.5, inplace=False)
    (2): MaxPool2d(kernel_size=2, stride=2, padding=0, dilation=1, ceil_mode=False)
  )
  (conv5): Sequential(
    (0): Conv2d(128, 128, kernel_size=(3, 3), stride=(1, 1), padding=(1, 1))
    (1): ReLU()
    (2): Dropout2d(p=0.5, inplace=False)
    (3): MaxPool2d(kernel_size=2, stride=2, padding=0, dilation=1, ceil_mode=False)
  )
  (conv6): Sequential(
    (0): Conv2d(128, 256, kernel_size=(3, 3), stride=(1, 1), padding=(1, 1))
    (1): ReLU()
    (2): Dropout2d(p=0.5, inplace=False)
    (3): MaxPool2d(kernel_size=2, stride=2, padding=0, dilation=1, ceil_mode=False)
  )
  (fc7): Sequential(
    (0): Linear(in_features=1024, out_features=512, bias=True)
    (1): ReLU()
    (2): Dropout2d(p=0.5, inplace=False)
  )
  (fc8): Linear(in_features=512, out_features=60, bias=True)
)
2021-06-16 16:20:20,788:INFO: Loading the datasets...
Exception in user code:
------------------------------------------------------------
Exception in user code:
------------------------------------------------------------
Exception in user code:
------------------------------------------------------------
Exception in user code:
------------------------------------------------------------
Exception in user code:
------------------------------------------------------------
weight initial finished!
Traceback (most recent call last):
  File "/home/hpc-0235/HCN-pytorch/feeder/feeder.py", line 72, in load_data
    with open(self.label_path) as f:
FileNotFoundError: [Errno 2] No such file or directory: './skeletonsNTU-RGB-D/xview/train_label.pkl'

During handling of the above exception, another exception occurred:

Traceback (most recent call last):
  File "main.py", line 513, in <module>
    train_dl = data_loader.fetch_dataloader('train', params)
  File "/home/hpc-0235/HCN-pytorch/data_loader.py", line 40, in fetch_dataloader
    dataset=Feeder(**params.train_feeder_args),
  File "/home/hpc-0235/HCN-pytorch/feeder/feeder.py", line 61, in __init__
    self.load_data()
  File "/home/hpc-0235/HCN-pytorch/feeder/feeder.py", line 76, in load_data
    with open(self.label_path, 'rb') as f:
FileNotFoundError: [Errno 2] No such file or directory: './skeletonsNTU-RGB-D/xview/train_label.pkl'
